Workbook
Name MinYears: Inputs!$B$10
Name Settle: Inputs!$B$6
Name Sv_beta0: Inputs!$B$13
Name Sv_beta1: Inputs!$B$14
Name Sv_beta2: Inputs!$B$15
Name Sv_beta3: Inputs!$B$16
Name Sv_tau1: Inputs!$B$17
Name Sv_tau2: Inputs!$B$18
Name Weighted_SSE: Inputs!$B$21

Sheet Cover
B2: Miniproject 2 - Creating a ZCB Term Structure
B3: FRE 6103 Valuation for Financial Engineering (NYU Tandon), Prof. David Shimko
B4: Raj Pawar | Data: WSJ / Tullett Prebon Treasury notes & bonds, 2026-09-04
B6: What this workbook does
B7: Fits a continuously compounded zero-coupon (ZCB) term structure to all US Treasury note and bond quotes using the Svensson (1994) functional form, then reports the discount rate r(t) and discount factor d(t) = exp(-r(t) t) for every Treasury payment date (coupons and principal).
B9: Sheet map
B10: Inputs: dates, Svensson parameters, objective (weighted SSE) and fit statistics. Solver runs here. Data: raw WSJ quotes exactly as downloaded. Bonds: one row per bond - 32nds conversion, coupon dates (COUPPCD/COUPNCD), accrued interest, dirty price, street yield (Excel YIELD), duration, model price off the curve, price and yield errors. CashFlows: every remaining coupon/principal date of every bond, its zero rate and present value. ZeroCurve: the deliverable - r(t), d(t) and instantaneous forward f(t) at every payment date, with chart. Robustness: convention check, Nelson-Siegel benchmark and beta0 profile (values computed by the Python implementation). Methodology: the one-page write-up.
B12: Live formulas
B13: Everything on Bonds, CashFlows and ZeroCurve is a formula. Change a parameter on Inputs and all model prices, errors and the curve update. Values on Data and Robustness are inputs/records.
B15: Re-running the fit with Solver
B16: Data > Solver. Set Objective: Inputs!$B$21 (weighted SSE) to Min. By Changing: Inputs!$B$13:$B$18. Subject to: $B$13 >= 0, $B$17 >= 0.05, $B$18 >= 0.05. Method: GRG Nonlinear; untick 'Make Unconstrained Variables Non-Negative' (beta1..beta3 may be negative). The pre-loaded parameters are already the optimum found by the Python implementation (multi-start least squares), so Solver should not move them materially.
B18: Companion Python implementation
B19: github.com/pawarraj8888/zcb-term-structure - identical conventions; the Excel SSE and every model price reproduce the Python numbers.

Sheet Inputs
B2: Inputs and fit
A4: Quote date (WSJ) | B4: 46269
A5: Market holiday (Labor Day) | B5: 46272
A6: Settlement date (T+1 business) | B6: =WORKDAY(B4,1,B5) -> 46273
A7: Face value | B7: 100
A8: Coupons per year | B8: 2
A9: Days per year (continuous time) | B9: 365
A10: Min years to maturity in fit | B10: 0.25
A12: Svensson parameters (continuous zero rate, decimals)
A13: beta0 | B13: 1.0489727e-13 | C13: level: r(t) as t -> infinity
A14: beta1 | B14: 0.036276273 | C14: slope: r(0) = beta0 + beta1
A15: beta2 | B15: 0.044721606 | C15: first hump, decay tau1
A16: beta3 | B16: 0.16228661 | C16: second hump, decay tau2
A17: tau1 | B17: 1.7660987 | C17: decay (years) of slope/first hump
A18: tau2 | B18: 15.991117 | C18: decay (years) of second hump
A20: Fit objective and statistics (bonds with In fit = 1)
A21: Weighted SSE = SUM( InFit x ((Pmodel - Pmkt) / ModDuration)^2 ) | B21: =SUM(Bonds!AA4:AA356) -> 0.26126611
A22: Bonds in fit | B22: =SUM(Bonds!S4:S356) -> 339
A23: Bonds total | B23: =COUNT(Bonds!B4:B356) -> 353
A24: Price RMSE (per 100 face) | B24: =SQRT(SUMPRODUCT(Bonds!S4:S356,Bonds!V4:V356,Bonds!V4:V356)/B22) -> 0.1852953
A25: Yield RMSE (bp) | B25: =SQRT(SUMPRODUCT(Bonds!S4:S356,Bonds!X4:X356,Bonds!X4:X356)/B22) -> 2.8823362
A26: Yield MAE (bp) | B26: =SUMPRODUCT(Bonds!S4:S356,ABS(Bonds!X4:X356))/B22 -> 2.0774758
A27: Max |yield error| (bp) | B27: =MAX(INDEX(Bonds!S4:S356*ABS(Bonds!X4:X356),0)) -> 14.817889
A28: r(0) = beta0 + beta1 (%) | B28: =(Sv_beta0+Sv_beta1)*100 -> 3.6276273
A29: r(30y) (%) | B29: =(Sv_beta0+Sv_beta1*(1-EXP(-30/Sv_tau1))/(30/Sv_tau1)+Sv_beta2*((1-EXP(-30/Sv_tau1))/(30/Sv_tau1)-EXP(-30/Sv_tau1))+Sv_beta3*((1-EXP(-30/Sv_tau2))/(30/Sv_tau2)-EXP(-30/Sv_tau2)))*100 -> 5.3159463
A31: Solver set-up
A32: Objective: $B$21 -> Min. Changing cells: $B$13:$B$18. Constraints: $B$13 >= 0, $B$17 >= 0.05, $B$18 >= 0.05. GRG Nonlinear; untick 'Make Unconstrained Variables Non-Negative'.
A35: Yellow cells are inputs; everything else is calculated.

Sheet Data
A1: U.S. Treasury Quotes - Treasury Notes & Bonds (WSJ, source Tullett Prebon). Prices in 32nds; third decimal = eighths of a 32nd.
A2: Maturity | B2: Coupon | C2: Bid | D2: Asked | E2: Chg | F2: Asked yield
A3: 46280 | B3: 4.625 | C3: 100 | D3: 100.01 | E3: -0.002 | F3: 2.937
A4: 46295 | B4: 0.875 | C4: 99.256 | D4: 99.266 | E4: 0.01 | F4: 3.625
A5: 46295 | B5: 1.625 | C5: 99.276 | D5: 99.286 | E5: 0.004 | F5: 3.318
A6: 46295 | B6: 3.5 | C6: 99.306 | D6: 99.316 | E6: 0.002 | F6: 3.603
A7: 46310 | B7: 4.625 | C7: 100.022 | D7: 100.032 | E7: -0.002 | F7: 3.576
A8: 46326 | B8: 1.125 | C8: 99.186 | D8: 99.196 | E8: 0.01 | F8: 3.808
A9: 46326 | B9: 1.625 | C9: 99.212 | D9: 99.222 | E9: 0.008 | F9: 3.755
A10: 46326 | B10: 4.125 | C10: 100 | D10: 100.01 | E10: -0.006 | F10: 3.877
A11: 46341 | B11: 2 | C11: 99.204 | D11: 99.214 | E11: 0.004 | F11: 3.787
A12: 46341 | B12: 4.625 | C12: 100.04 | D12: 100.05 | E12: -0.002 | F12: 3.741
A13: 46341 | B13: 6.5 | C13: 100.13 | D13: 100.14 | E13: -0.014 | F13: 4.058
A14: 46356 | B14: 1.25 | C14: 99.126 | D14: 99.136 | E14: 0.006 | F14: 3.793
... A20: 46387 | B20: 4.25 | C20: 100.024 | D20: 100.034 | E20: -0.002 | F20: 3.876
A21: 46402 | B21: 4 | C21: 100.01 | D21: 100.02 | E21: unch. | F21: 3.807
A22: 46418 | B22: 1.5 | C22: 99.004 | D22: 99.014 | E22: 0.688 | F22: 3.959
A23: 46418 | B23: 4.125 | C23: 100.01 | D23: 100.02 | E23: 0.004 | F23: 3.955
A24: 46433 | B24: 2.25 | C24: 99.082 | D24: 99.092 | E24: 0.006 | F24: 3.912
A25: 46433 | B25: 4.125 | C25: 100.012 | D25: 100.022 | E25: -0.008 | F25: 3.955
A26: 46433 | B26: 6.625 | C26: 101.03 | D26: 101.04 | E26: -0.02 | F26: 3.981
A27: 46446 | B27: 1.125 | C27: 98.202 | D27: 98.212 | E27: 0.008 | F27: 3.974
A28: 46446 | B28: 1.875 | C28: 99.002 | D28: 99.012 | E28: 0.686 | F28: 3.923
A29: 46446 | B29: 4.125 | C29: 100.016 | D29: 100.026 | E29: unch. | F29: 3.94
A30: 46461 | B30: 4.25 | C30: 100.042 | D30: 100.052 | E30: -0.002 | F30: 3.926
A31: 46477 | B31: 0.625 | C31: 98.042 | D31: 98.052 | E31: 0.01 | F31: 3.971
A32: 46477 | B32: 2.5 | C32: 99.052 | D32: 99.062 | E32: 0.002 | F32: 3.964
A33: 46477 | B33: 3.875 | C33: 99.294 | D33: 99.304 | E33: 0.002 | F33: 3.957
A34: 46492 | B34: 4.5 | C34: 100.082 | D34: 100.092 | E34: unch. | F34: 4.002
A35: 46507 | B35: 0.5 | C35: 97.24 | D35: 97.25 | E35: 0.016 | F35: 4.024
A36: 46507 | B36: 2.75 | C36: 99.044 | D36: 99.054 | E36: unch. | F36: 4.061
A37: 46507 | B37: 3.75 | C37: 99.254 | D37: 99.264 | E37: 0.008 | F37: 4.017
A38: 46522 | B38: 2.375 | C38: 98.262 | D38: 98.272 | E38: 0.002 | F38: 4.089
A39: 46522 | B39: 4.5 | C39: 100.074 | D39: 100.084 | E39: -0.006 | F39: 4.095
A40: 46538 | B40: 0.5 | C40: 97.14 | D40: 97.15 | E40: 0.01 | F40: 4.069
A41: 46538 | B41: 2.625 | C41: 98.302 | D41: 98.312 | E41: 0.008 | F41: 4.064
A42: 46538 | B42: 3.875 | C42: 99.262 | D42: 99.272 | E42: -0.002 | F42: 4.078
A43: 46553 | B43: 4.625 | C43: 100.114 | D43: 100.124 | E43: -0.002 | F43: 4.095
A44: 46568 | B44: 0.5 | C44: 97.034 | D44: 97.044 | E44: 0.008 | F44: 4.126
A45: 46568 | B45: 3.25 | C45: 99.092 | D45: 99.102 | E45: unch. | F45: 4.107
...

Sheet Bonds
A1: Per-bond mechanics with Excel bond functions (basis 1 = actual/actual, frequency 2). Coupon-period days are taken as COUPNCD - COUPPCD because COUPDAYS(basis 1) mis-states some month-end periods (183 vs 184 days). Model prices come from the CashFlows sheet.
A3: # | B3: Maturity | C3: Coupon % | D3: Bid (WSJ) | E3: Ask (WSJ) | F3: WSJ asked yield % | G3: Ask clean price (decimal) | H3: Previous coupon | I3: Next coupon | J3: Days accrued (settle - prev) | K3: Days in period (next - prev) | L3: Accrued interest | M3: Dirty price | N3: Street yield % (Excel YIELD) | O3: Yield check vs WSJ (bp) | P3: Modified duration | Q3: Remaining cash flows | R3: Years to maturity | S3: In fit (1/0) | T3: Model dirty price | U3: Model clean price | V3: Price error (model - mkt) | W3: Model yield % | X3: Yield error (bp) | Y3: Weight = 1 / duration | Z3: Weighted residual | AA3: Weighted sq. residual (in fit)
A4: 1 | B4: =Data!A3 -> 46280 | C4: =Data!B3 -> 4.625 | D4: =Data!C3 -> 100 | E4: =Data!D3 -> 100.01 | F4: =Data!F3 -> 2.937 | G4: =INT(E4)+(VALUE(MID(TEXT(E4,"0.000"),FIND(".",TEXT(E4,"0.000"))+1,2))+VALUE(RIGHT(TEXT(E4,"0.000"),1))/8)/32 -> 100.03125 | H4: =COUPPCD(Settle,B4,2,1) -> 46096 | I4: =COUPNCD(Settle,B4,2,1) -> 46280 | J4: =Settle-H4 -> 177 | K4: =I4-H4 -> 184 | L4: =C4/2*J4/K4 -> 2.2245245 | M4: =G4+L4 -> 102.25577 | N4: =YIELD(Settle,B4,C4/100,G4,100,2,1)*100 -> 2.9163564 | O4: =(N4-F4)*100 -> -2.0643566 | P4: =MDURATION(Settle,B4,C4/100,N4/100,2,1) -> 0.018748355 | Q4: =COUPNUM(Settle,B4,2,1) -> 1 | R4: =(B4-Settle)/365 -> 0.019178082 | S4: =IF(R4>=MinYears,1,0) -> 0 | T4: =SUM(CashFlows!DX4:GE4) -> 102.24107 | U4: =T4-L4 -> 100.01654 | V4: =U4-G4 -> -0.014707997 | W4: =YIELD(Settle,B4,C4/100,U4,100,2,1)*100 -> 3.6730478 | X4: =(W4-N4)*100 -> 75.669138 | Y4: =1/P4 -> 53.338014 | Z4: =Y4*(T4-M4) -> -0.78449533 | AA4: =S4*Z4^2 -> 0
A5: 2 | B5: =Data!A4 -> 46295 | C5: =Data!B4 -> 0.875 | D5: =Data!C4 -> 99.256 | E5: =Data!D4 -> 99.266 | F5: =Data!F4 -> 3.625 | G5: =INT(E5)+(VALUE(MID(TEXT(E5,"0.000"),FIND(".",TEXT(E5,"0.000"))+1,2))+VALUE(RIGHT(TEXT(E5,"0.000"),1))/8)/32 -> 99.835938 | H5: =COUPPCD(Settle,B5,2,1) -> 46112 | I5: =COUPNCD(Settle,B5,2,1) -> 46295 | J5: =Settle-H5 -> 161 | K5: =I5-H5 -> 183 | L5: =C5/2*J5/K5 -> 0.38490437 | M5: =G5+L5 -> 100.22084 | N5: =YIELD(Settle,B5,C5/100,G5,100,2,1)*100 -> 3.5964609 | O5: =(N5-F5)*100 -> -2.8539083 | P5: =MDURATION(Settle,B5,C5/100,N5/100,2,1) -> 0.05904748 | Q5: =COUPNUM(Settle,B5,2,1) -> 1 | R5: =(B5-Settle)/365 -> 0.060273973 | S5: =IF(R5>=MinYears,1,0) -> 0 | T5: =SUM(CashFlows!DX5:GE5) -> 100.21548 | U5: =T5-L5 -> 99.830575 | V5: =U5-G5 -> -0.0053620183 | W5: =YIELD(Settle,B5,C5/100,U5,100,2,1)*100 -> 3.685666 | X5: =(W5-N5)*100 -> 8.920511 | Y5: =1/P5 -> 16.935524 | Z5: =Y5*(T5-M5) -> -0.090808588 | AA5: =S5*Z5^2 -> 0
A6: 3 | B6: =Data!A5 -> 46295 | C6: =Data!B5 -> 1.625 | D6: =Data!C5 -> 99.276 | E6: =Data!D5 -> 99.286 | F6: =Data!F5 -> 3.318 | G6: =INT(E6)+(VALUE(MID(TEXT(E6,"0.000"),FIND(".",TEXT(E6,"0.000"))+1,2))+VALUE(RIGHT(TEXT(E6,"0.000"),1))/8)/32 -> 99.898438 | H6: =COUPPCD(Settle,B6,2,1) -> 46112 | I6: =COUPNCD(Settle,B6,2,1) -> 46295 | J6: =Settle-H6 -> 161 | K6: =I6-H6 -> 183 | L6: =C6/2*J6/K6 -> 0.7148224 | M6: =G6+L6 -> 100.61326 | N6: =YIELD(Settle,B6,C6/100,G6,100,2,1)*100 -> 3.2944273 | O6: =(N6-F6)*100 -> -2.357272 | P6: =MDURATION(Settle,B6,C6/100,N6/100,2,1) -> 0.059135206 | Q6: =COUPNUM(Settle,B6,2,1) -> 1 | R6: =(B6-Settle)/365 -> 0.060273973 | S6: =IF(R6>=MinYears,1,0) -> 0 | T6: =SUM(CashFlows!DX6:GE6) -> 100.58965 | U6: =T6-L6 -> 99.874829 | V6: =U6-G6 -> -0.023609 | W6: =YIELD(Settle,B6,C6/100,U6,100,2,1)*100 -> 3.685666 | X6: =(W6-N6)*100 -> 39.123875 | Y6: =1/P6 -> 16.9104 | Z6: =Y6*(T6-M6) -> -0.39923764 | AA6: =S6*Z6^2 -> 0
A7: 4 | B7: =Data!A6 -> 46295 | C7: =Data!B6 -> 3.5 | D7: =Data!C6 -> 99.306 | E7: =Data!D6 -> 99.316 | F7: =Data!F6 -> 3.603 | G7: =INT(E7)+(VALUE(MID(TEXT(E7,"0.000"),FIND(".",TEXT(E7,"0.000"))+1,2))+VALUE(RIGHT(TEXT(E7,"0.000"),1))/8)/32 -> 99.992188 | H7: =COUPPCD(Settle,B7,2,1) -> 46112 | I7: =COUPNCD(Settle,B7,2,1) -> 46295 | J7: =Settle-H7 -> 161 | K7: =I7-H7 -> 183 | L7: =C7/2*J7/K7 -> 1.5396175 | M7: =G7+L7 -> 101.5318 | N7: =YIELD(Settle,B7,C7/100,G7,100,2,1)*100 -> 3.5752064 | O7: =(N7-F7)*100 -> -2.7793599 | P7: =MDURATION(Settle,B7,C7/100,N7/100,2,1) -> 0.059053645 | Q7: =COUPNUM(Settle,B7,2,1) -> 1 | R7: =(B7-Settle)/365 -> 0.060273973 | S7: =IF(R7>=MinYears,1,0) -> 0 | T7: =SUM(CashFlows!DX7:GE7) -> 101.52508 | U7: =T7-L7 -> 99.985461 | V7: =U7-G7 -> -0.0067264542 | W7: =YIELD(Settle,B7,C7/100,U7,100,2,1)*100 -> 3.685666 | X7: =(W7-N7)*100 -> 11.045963 | Y7: =1/P7 -> 16.933756 | Z7: =Y7*(T7-M7) -> -0.11390413 | AA7: =S7*Z7^2 -> 0
A8: 5 | B8: =Data!A7 -> 46310 | C8: =Data!B7 -> 4.625 | D8: =Data!C7 -> 100.022 | E8: =Data!D7 -> 100.032 | F8: =Data!F7 -> 3.576 | G8: =INT(E8)+(VALUE(MID(TEXT(E8,"0.000"),FIND(".",TEXT(E8,"0.000"))+1,2))+VALUE(RIGHT(TEXT(E8,"0.000"),1))/8)/32 -> 100.10156 | H8: =COUPPCD(Settle,B8,2,1) -> 46127 | I8: =COUPNCD(Settle,B8,2,1) -> 46310 | J8: =Settle-H8 -> 146 | K8: =I8-H8 -> 183 | L8: =C8/2*J8/K8 -> 1.8449454 | M8: =G8+L8 -> 101.94651 | N8: =YIELD(Settle,B8,C8/100,G8,100,2,1)*100 -> 3.5512298 | O8: =(N8-F8)*100 -> -2.4770237 | P8: =MDURATION(Settle,B8,C8/100,N8/100,2,1) -> 0.099329192 | Q8: =COUPNUM(Settle,B8,2,1) -> 1 | R8: =(B8-Settle)/365 -> 0.10136986 | S8: =IF(R8>=MinYears,1,0) -> 0 | T8: =SUM(CashFlows!DX8:GE8) -> 101.92945 | U8: =T8-L8 -> 100.08451 | V8: =U8-G8 -> -0.017056054 | W8: =YIELD(Settle,B8,C8/100,U8,100,2,1)*100 -> 3.717347 | X8: =(W8-N8)*100 -> 16.611719 | Y8: =1/P8 -> 10.067534 | Z8: =Y8*(T8-M8) -> -0.1717124 | AA8: =S8*Z8^2 -> 0
A9: 6 | B9: =Data!A8 -> 46326 | C9: =Data!B8 -> 1.125 | D9: =Data!C8 -> 99.186 | E9: =Data!D8 -> 99.196 | F9: =Data!F8 -> 3.808 | G9: =INT(E9)+(VALUE(MID(TEXT(E9,"0.000"),FIND(".",TEXT(E9,"0.000"))+1,2))+VALUE(RIGHT(TEXT(E9,"0.000"),1))/8)/32 -> 99.617188 | H9: =COUPPCD(Settle,B9,2,1) -> 46142 | I9: =COUPNCD(Settle,B9,2,1) -> 46326 | J9: =Settle-H9 -> 131 | K9: =I9-H9 -> 184 | L9: =C9/2*J9/K9 -> 0.40047554 | M9: =G9+L9 -> 100.01766 | N9: =YIELD(Settle,B9,C9/100,G9,100,2,1)*100 -> 3.7823508 | O9: =(N9-F9)*100 -> -2.564921 | P9: =MDURATION(Settle,B9,C9/100,N9/100,2,1) -> 0.14134859 | Q9: =COUPNUM(Settle,B9,2,1) -> 1 | R9: =(B9-Settle)/365 -> 0.14520548 | S9: =IF(R9>=MinYears,1,0) -> 0 | T9: =SUM(CashFlows!DX9:GE9) -> 100.01934 | U9: =T9-L9 -> 99.618861 | V9: =U9-G9 -> 0.001673366 | W9: =YIELD(Settle,B9,C9/100,U9,100,2,1)*100 -> 3.7706709 | X9: =(W9-N9)*100 -> -1.1679877 | Y9: =1/P9 -> 7.074708 | Z9: =Y9*(T9-M9) -> 0.011838576 | AA9: =S9*Z9^2 -> 0
A10: 7 | B10: =Data!A9 -> 46326 | C10: =Data!B9 -> 1.625 | D10: =Data!C9 -> 99.212 | E10: =Data!D9 -> 99.222 | F10: =Data!F9 -> 3.755 | G10: =INT(E10)+(VALUE(MID(TEXT(E10,"0.000"),FIND(".",TEXT(E10,"0.000"))+1,2))+VALUE(RIGHT(TEXT(E10,"0.000"),1))/8)/32 -> 99.695312 | H10: =COUPPCD(Settle,B10,2,1) -> 46142 | I10: =COUPNCD(Settle,B10,2,1) -> 46326 | J10: =Settle-H10 -> 131 | K10: =I10-H10 -> 184 | L10: =C10/2*J10/K10 -> 0.57846467 | M10: =G10+L10 -> 100.27378 | N10: =YIELD(Settle,B10,C10/100,G10,100,2,1)*100 -> 3.7303532 | O10: =(N10-F10)*100 -> -2.4646818 | P10: =MDURATION(Settle,B10,C10/100,N10/100,2,1) -> 0.14138467 | Q10: =COUPNUM(Settle,B10,2,1) -> 1 | R10: =(B10-Settle)/365 -> 0.14520548 | S10: =IF(R10>=MinYears,1,0) -> 0 | T10: =SUM(CashFlows!DX10:GE10) -> 100.26799 | U10: =T10-L10 -> 99.689521 | V10: =U10-G10 -> -0.0057910779 | W10: =YIELD(Settle,B10,C10/100,U10,100,2,1)*100 -> 3.7706709 | X10: =(W10-N10)*100 -> 4.031773 | Y10: =1/P10 -> 7.0729028 | Z10: =Y10*(T10-M10) -> -0.040959731 | AA10: =S10*Z10^2 -> 0
A11: 8 | B11: =Data!A10 -> 46326 | C11: =Data!B10 -> 4.125 | D11: =Data!C10 -> 100 | E11: =Data!D10 -> 100.01 | F11: =Data!F10 -> 3.877 | G11: =INT(E11)+(VALUE(MID(TEXT(E11,"0.000"),FIND(".",TEXT(E11,"0.000"))+1,2))+VALUE(RIGHT(TEXT(E11,"0.000"),1))/8)/32 -> 100.03125 | H11: =COUPPCD(Settle,B11,2,1) -> 46142 | I11: =COUPNCD(Settle,B11,2,1) -> 46326 | J11: =Settle-H11 -> 131 | K11: =I11-H11 -> 184 | L11: =C11/2*J11/K11 -> 1.4684103 | M11: =G11+L11 -> 101.49966 | N11: =YIELD(Settle,B11,C11/100,G11,100,2,1)*100 -> 3.8502778 | O11: =(N11-F11)*100 -> -2.672222 | P11: =MDURATION(Settle,B11,C11/100,N11/100,2,1) -> 0.14130149 | Q11: =COUPNUM(Settle,B11,2,1) -> 1 | R11: =(B11-Settle)/365 -> 0.14520548 | S11: =IF(R11>=MinYears,1,0) -> 0 | T11: =SUM(CashFlows!DX11:GE11) -> 101.51123 | U11: =T11-L11 -> 100.04282 | V11: =U11-G11 -> 0.011574203 | W11: =YIELD(Settle,B11,C11/100,U11,100,2,1)*100 -> 3.7706709 | X11: =(W11-N11)*100 -> -7.9606867 | Y11: =1/P11 -> 7.0770662 | Z11: =Y11*(T11-M11) -> 0.081911398 | AA11: =S11*Z11^2 -> 0
A12: 9 | B12: =Data!A11 -> 46341 | C12: =Data!B11 -> 2 | D12: =Data!C11 -> 99.204 | E12: =Data!D11 -> 99.214 | F12: =Data!F11 -> 3.787 | G12: =INT(E12)+(VALUE(MID(TEXT(E12,"0.000"),FIND(".",TEXT(E12,"0.000"))+1,2))+VALUE(RIGHT(TEXT(E12,"0.000"),1))/8)/32 -> 99.671875 | H12: =COUPPCD(Settle,B12,2,1) -> 46157 | I12: =COUPNCD(Settle,B12,2,1) -> 46341 | J12: =Settle-H12 -> 116 | K12: =I12-H12 -> 184 | L12: =C12/2*J12/K12 -> 0.63043478 | M12: =G12+L12 -> 100.30231 | N12: =YIELD(Settle,B12,C12/100,G12,100,2,1)*100 -> 3.7643553 | O12: =(N12-F12)*100 -> -2.264472 | P12: =MDURATION(Settle,B12,C12/100,N12/100,2,1) -> 0.18136892 | Q12: =COUPNUM(Settle,B12,2,1) -> 1 | R12: =(B12-Settle)/365 -> 0.18630137 | S12: =IF(R12>=MinYears,1,0) -> 0 | T12: =SUM(CashFlows!DX12:GE12) -> 100.29561 | U12: =T12-L12 -> 99.665179 | V12: =U12-G12 -> -0.0066963481 | W12: =YIELD(Settle,B12,C12/100,U12,100,2,1)*100 -> 3.8007389 | X12: =(W12-N12)*100 -> 3.638358 | Y12: =1/P12 -> 5.5136237 | Z12: =Y12*(T12-M12) -> -0.036921144 | AA12: =S12*Z12^2 -> 0
A13: 10 | B13: =Data!A12 -> 46341 | C13: =Data!B12 -> 4.625 | D13: =Data!C12 -> 100.04 | E13: =Data!D12 -> 100.05 | F13: =Data!F12 -> 3.741 | G13: =INT(E13)+(VALUE(MID(TEXT(E13,"0.000"),FIND(".",TEXT(E13,"0.000"))+1,2))+VALUE(RIGHT(TEXT(E13,"0.000"),1))/8)/32 -> 100.15625 | H13: =COUPPCD(Settle,B13,2,1) -> 46157 | I13: =COUPNCD(Settle,B13,2,1) -> 46341 | J13: =Settle-H13 -> 116 | K13: =I13-H13 -> 184 | L13: =C13/2*J13/K13 -> 1.4578804 | M13: =G13+L13 -> 101.61413 | N13: =YIELD(Settle,B13,C13/100,G13,100,2,1)*100 -> 3.7193762 | O13: =(N13-F13)*100 -> -2.1623818 | P13: =MDURATION(Settle,B13,C13/100,N13/100,2,1) -> 0.18140897 | Q13: =COUPNUM(Settle,B13,2,1) -> 1 | R13: =(B13-Settle)/365 -> 0.18630137 | S13: =IF(R13>=MinYears,1,0) -> 0 | T13: =SUM(CashFlows!DX13:GE13) -> 101.59896 | U13: =T13-L13 -> 100.14108 | V13: =U13-G13 -> -0.015170539 | W13: =YIELD(Settle,B13,C13/100,U13,100,2,1)*100 -> 3.8007389 | X13: =(W13-N13)*100 -> 8.1362678 | Y13: =1/P13 -> 5.5124066 | Z13: =Y13*(T13-M13) -> -0.083626178 | AA13: =S13*Z13^2 -> 0
A14: 11 | B14: =Data!A13 -> 46341 | C14: =Data!B13 -> 6.5 | D14: =Data!C13 -> 100.13 | E14: =Data!D13 -> 100.14 | F14: =Data!F13 -> 4.058 | G14: =INT(E14)+(VALUE(MID(TEXT(E14,"0.000"),FIND(".",TEXT(E14,"0.000"))+1,2))+VALUE(RIGHT(TEXT(E14,"0.000"),1))/8)/32 -> 100.4375 | H14: =COUPPCD(Settle,B14,2,1) -> 46157 | I14: =COUPNCD(Settle,B14,2,1) -> 46341 | J14: =Settle-H14 -> 116 | K14: =I14-H14 -> 184 | L14: =C14/2*J14/K14 -> 2.048913 | M14: =G14+L14 -> 102.48641 | N14: =YIELD(Settle,B14,C14/100,G14,100,2,1)*100 -> 4.0320983 | O14: =(N14-F14)*100 -> -2.5901677 | P14: =MDURATION(Settle,B14,C14/100,N14/100,2,1) -> 0.18113092 | Q14: =COUPNUM(Settle,B14,2,1) -> 1 | R14: =(B14-Settle)/365 -> 0.18630137 | S14: =IF(R14>=MinYears,1,0) -> 0 | T14: =SUM(CashFlows!DX14:GE14) -> 102.52992 | U14: =T14-L14 -> 100.48101 | V14: =U14-G14 -> 0.043508611 | W14: =YIELD(Settle,B14,C14/100,U14,100,2,1)*100 -> 3.8007389 | X14: =(W14-N14)*100 -> -23.135946 | Y14: =1/P14 -> 5.5208685 | Z14: =Y14*(T14-M14) -> 0.24020532 | AA14: =S14*Z14^2 -> 0
A15: 12 | B15: =Data!A14 -> 46356 | C15: =Data!B14 -> 1.25 | D15: =Data!C14 -> 99.126 | E15: =Data!D14 -> 99.136 | F15: =Data!F14 -> 3.793 | G15: =INT(E15)+(VALUE(MID(TEXT(E15,"0.000"),FIND(".",TEXT(E15,"0.000"))+1,2))+VALUE(RIGHT(TEXT(E15,"0.000"),1))/8)/32 -> 99.429688 | H15: =COUPPCD(Settle,B15,2,1) -> 46173 | I15: =COUPNCD(Settle,B15,2,1) -> 46356 | J15: =Settle-H15 -> 100 | K15: =I15-H15 -> 183 | L15: =C15/2*J15/K15 -> 0.34153005 | M15: =G15+L15 -> 99.771218 | N15: =YIELD(Settle,B15,C15/100,G15,100,2,1)*100 -> 3.7735051 | O15: =(N15-F15)*100 -> -1.9494895 | P15: =MDURATION(Settle,B15,C15/100,N15/100,2,1) -> 0.22257649 | Q15: =COUPNUM(Settle,B15,2,1) -> 1 | R15: =(B15-Settle)/365 -> 0.22739726 | S15: =IF(R15>=MinYears,1,0) -> 0 | T15: =SUM(CashFlows!DX15:GE15) -> 99.763218 | U15: =T15-L15 -> 99.421688 | V15: =U15-G15 -> -0.0079994508 | W15: =YIELD(Settle,B15,C15/100,U15,100,2,1)*100 -> 3.8091661 | X15: =(W15-N15)*100 -> 3.5660985 | Y15: =1/P15 -> 4.4928375 | Z15: =Y15*(T15-M15) -> -0.035940233 | AA15: =S15*Z15^2 -> 0
... A356: 353 | B356: =Data!A355 -> 57207 | C356: =Data!B355 -> 5.125 | D356: =Data!C355 -> 98.06 | E356: =Data!D355 -> 98.08 | F356: =Data!F355 -> 5.241 | G356: =INT(E356)+(VALUE(MID(TEXT(E356,"0.000"),FIND(".",TEXT(E356,"0.000"))+1,2))+VALUE(RIGHT(TEXT(E356,"0.000"),1))/8)/32 -> 98.25 | H356: =COUPPCD(Settle,B356,2,1) -> 46249 | I356: =COUPNCD(Settle,B356,2,1) -> 46433 | J356: =Settle-H356 -> 24 | K356: =I356-H356 -> 184 | L356: =C356/2*J356/K356 -> 0.33423913 | M356: =G356+L356 -> 98.584239 | N356: =YIELD(Settle,B356,C356/100,G356,100,2,1)*100 -> 5.2412244 | O356: =(N356-F356)*100 -> 0.02244479 | P356: =MDURATION(Settle,B356,C356/100,N356/100,2,1) -> 15.042795 | Q356: =COUPNUM(Settle,B356,2,1) -> 60 | R356: =(B356-Settle)/365 -> 29.956164 | S356: =IF(R356>=MinYears,1,0) -> 1 | T356: =SUM(CashFlows!DX356:GE356) -> 98.324946 | U356: =T356-L356 -> 97.990707 | V356: =U356-G356 -> -0.25929283 | W356: =YIELD(Settle,B356,C356/100,U356,100,2,1)*100 -> 5.2587434 | X356: =(W356-N356)*100 -> 1.7518997 | Y356: =1/P356 -> 0.06647701 | Z356: =Y356*(T356-M356) -> -0.017237012 | AA356: =S356*Z356^2 -> 0.00029711457

Sheet CashFlows
A1: Every remaining payment of every bond. Block 1: payment dates (k-th coupon after settlement). Block 2: Svensson zero rate r(t_k). Block 3: present value = amount x exp(-r t). Model dirty price = row sum of block 3.
F2: Payment dates | BO2: Zero rates (continuous, decimal) | DX2: Present values (per 100 face)
A3: # | B3: Maturity | C3: Coupon % | D3: Remaining flows N | E3: Month-end (1/0) | F3: Date 1 | G3: Date 2 | H3: Date 3 | I3: Date 4 | J3: Date 5 | K3: Date 6 | L3: Date 7 | M3: Date 8 | N3: Date 9 | O3: Date 10 | P3: Date 11 | Q3: Date 12 | R3: Date 13 | S3: Date 14 | T3: Date 15 | U3: Date 16 | V3: Date 17 | W3: Date 18 | X3: Date 19 | Y3: Date 20 | Z3: Date 21 | AA3: Date 22 | AB3: Date 23 | AC3: Date 24 | AD3: Date 25 | AE3: Date 26 | AF3: Date 27 | AG3: Date 28 | AH3: Date 29 | AI3: Date 30 | AJ3: Date 31 | AK3: Date 32 | AL3: Date 33 | AM3: Date 34 | AN3: Date 35 | AO3: Date 36 | AP3: Date 37 | AQ3: Date 38 | AR3: Date 39 | AS3: Date 40 | AT3: Date 41 | AU3: Date 42 | AV3: Date 43 | AW3: Date 44 | AX3: Date 45 | AY3: Date 46 | AZ3: Date 47 | BA3: Date 48 | BB3: Date 49 | BC3: Date 50 | BD3: Date 51 | BE3: Date 52 | BF3: Date 53 | BG3: Date 54 | BH3: Date 55 | BI3: Date 56 | BJ3: Date 57 | BK3: Date 58 | BL3: Date 59 | BM3: Date 60 | BO3: r(t) 1 | BP3: r(t) 2 | BQ3: r(t) 3 | BR3: r(t) 4 | BS3: r(t) 5 | BT3: r(t) 6 | BU3: r(t) 7 | BV3: r(t) 8 | BW3: r(t) 9 | BX3: r(t) 10 | BY3: r(t) 11 | BZ3: r(t) 12 | CA3: r(t) 13 | CB3: r(t) 14 | CC3: r(t) 15 | CD3: r(t) 16 | CE3: r(t) 17 | CF3: r(t) 18 | CG3: r(t) 19 | CH3: r(t) 20 | CI3: r(t) 21 | CJ3: r(t) 22 | CK3: r(t) 23 | CL3: r(t) 24 | CM3: r(t) 25 | CN3: r(t) 26 | CO3: r(t) 27 | CP3: r(t) 28 | CQ3: r(t) 29 | CR3: r(t) 30 | CS3: r(t) 31 | CT3: r(t) 32 | CU3: r(t) 33 | CV3: r(t) 34 | CW3: r(t) 35 | CX3: r(t) 36 | CY3: r(t) 37 | CZ3: r(t) 38 | DA3: r(t) 39 | DB3: r(t) 40 | DC3: r(t) 41 | DD3: r(t) 42 | DE3: r(t) 43 | DF3: r(t) 44 | DG3: r(t) 45 | DH3: r(t) 46 | DI3: r(t) 47 | DJ3: r(t) 48 | DK3: r(t) 49 | DL3: r(t) 50 | DM3: r(t) 51 | DN3: r(t) 52 | DO3: r(t) 53 | DP3: r(t) 54 | DQ3: r(t) 55 | DR3: r(t) 56 | DS3: r(t) 57 | DT3: r(t) 58 | DU3: r(t) 59 | DV3: r(t) 60 | DX3: PV 1 | DY3: PV 2 | DZ3: PV 3 | EA3: PV 4 | EB3: PV 5 | EC3: PV 6 | ED3: PV 7 | EE3: PV 8 | EF3: PV 9 | EG3: PV 10 | EH3: PV 11 | EI3: PV 12 | EJ3: PV 13 | EK3: PV 14 | EL3: PV 15 | EM3: PV 16 | EN3: PV 17 | EO3: PV 18 | EP3: PV 19 | EQ3: PV 20 | ER3: PV 21 | ES3: PV 22 | ET3: PV 23 | EU3: PV 24 | EV3: PV 25 | EW3: PV 26 | EX3: PV 27 | EY3: PV 28 | EZ3: PV 29 | FA3: PV 30 | FB3: PV 31 | FC3: PV 32 | FD3: PV 33 | FE3: PV 34 | FF3: PV 35 | FG3: PV 36 | FH3: PV 37 | FI3: PV 38 | FJ3: PV 39 | FK3: PV 40 | FL3: PV 41 | FM3: PV 42 | FN3: PV 43 | FO3: PV 44 | FP3: PV 45 | FQ3: PV 46 | FR3: PV 47 | FS3: PV 48 | FT3: PV 49 | FU3: PV 50 | FV3: PV 51 | FW3: PV 52 | FX3: PV 53 | FY3: PV 54 | FZ3: PV 55 | GA3: PV 56 | GB3: PV 57 | GC3: PV 58 | GD3: PV 59 | GE3: PV 60
A4: 1 | B4: =Bonds!B4 -> 46280 | C4: =Bonds!C4 -> 4.625 | D4: =Bonds!Q4 -> 1 | E4: =IF(DAY(B4)=DAY(EOMONTH(B4,0)),1,0) -> 0 | F4: =IF(1>$D4,"",IF($E4=1,EOMONTH(EDATE(Bonds!$I4,6*(1-1)),0),EDATE(Bonds!$I4,6*(1-1)))) -> 46280 | G4: =IF(2>$D4,"",IF($E4=1,EOMONTH(EDATE(Bonds!$I4,6*(2-1)),0),EDATE(Bonds!$I4,6*(2-1)))) | H4: =IF(3>$D4,"",IF($E4=1,EOMONTH(EDATE(Bonds!$I4,6*(3-1)),0),EDATE(Bonds!$I4,6*(3-1)))) | I4: =IF(4>$D4,"",IF($E4=1,EOMONTH(EDATE(Bonds!$I4,6*(4-1)),0),EDATE(Bonds!$I4,6*(4-1)))) | J4: =IF(5>$D4,"",IF($E4=1,EOMONTH(EDATE(Bonds!$I4,6*(5-1)),0),EDATE(Bonds!$I4,6*(5-1)))) | K4: =IF(6>$D4,"",IF($E4=1,EOMONTH(EDATE(Bonds!$I4,6*(6-1)),0),EDATE(Bonds!$I4,6*(6-1)))) | L4: =IF(7>$D4,"",IF($E4=1,EOMONTH(EDATE(Bonds!$I4,6*(7-1)),0),EDATE(Bonds!$I4,6*(7-1)))) | M4: =IF(8>$D4,"",IF($E4=1,EOMONTH(EDATE(Bonds!$I4,6*(8-1)),0),EDATE(Bonds!$I4,6*(8-1)))) | N4: =IF(9>$D4,"",IF($E4=1,EOMONTH(EDATE(Bonds!$I4,6*(9-1)),0),EDATE(Bonds!$I4,6*(9-1)))) | O4: =IF(10>$D4,"",IF($E4=1,EOMONTH(EDATE(Bonds!$I4,6*(10-1)),0),EDATE(Bonds!$I4,6*(10-1)))) | P4: =IF(11>$D4,"",IF($E4=1,EOMONTH(EDATE(Bonds!$I4,6*(11-1)),0),EDATE(Bonds!$I4,6*(11-1)))) | Q4: =IF(12>$D4,"",IF($E4=1,EOMONTH(EDATE(Bonds!$I4,6*(12-1)),0),EDATE(Bonds!$I4,6*(12-1)))) | R4: =IF(13>$D4,"",IF($E4=1,EOMONTH(EDATE(Bonds!$I4,6*(13-1)),0),EDATE(Bonds!$I4,6*(13-1)))) | S4: =IF(14>$D4,"",IF($E4=1,EOMONTH(EDATE(Bonds!$I4,6*(14-1)),0),EDATE(Bonds!$I4,6*(14-1)))) | T4: =IF(15>$D4,"",IF($E4=1,EOMONTH(EDATE(Bonds!$I4,6*(15-1)),0),EDATE(Bonds!$I4,6*(15-1)))) | U4: =IF(16>$D4,"",IF($E4=1,EOMONTH(EDATE(Bonds!$I4,6*(16-1)),0),EDATE(Bonds!$I4,6*(16-1)))) | V4: =IF(17>$D4,"",IF($E4=1,EOMONTH(EDATE(Bonds!$I4,6*(17-1)),0),EDATE(Bonds!$I4,6*(17-1)))) | W4: =IF(18>$D4,"",IF($E4=1,EOMONTH(EDATE(Bonds!$I4,6*(18-1)),0),EDATE(Bonds!$I4,6*(18-1)))) | X4: =IF(19>$D4,"",IF($E4=1,EOMONTH(EDATE(Bonds!$I4,6*(19-1)),0),EDATE(Bonds!$I4,6*(19-1)))) | Y4: =IF(20>$D4,"",IF($E4=1,EOMONTH(EDATE(Bonds!$I4,6*(20-1)),0),EDATE(Bonds!$I4,6*(20-1)))) | Z4: =IF(21>$D4,"",IF($E4=1,EOMONTH(EDATE(Bonds!$I4,6*(21-1)),0),EDATE(Bonds!$I4,6*(21-1)))) | AA4: =IF(22>$D4,"",IF($E4=1,EOMONTH(EDATE(Bonds!$I4,6*(22-1)),0),EDATE(Bonds!$I4,6*(22-1)))) | AB4: =IF(23>$D4,"",IF($E4=1,EOMONTH(EDATE(Bonds!$I4,6*(23-1)),0),EDATE(Bonds!$I4,6*(23-1)))) | AC4: =IF(24>$D4,"",IF($E4=1,EOMONTH(EDATE(Bonds!$I4,6*(24-1)),0),EDATE(Bonds!$I4,6*(24-1)))) | AD4: =IF(25>$D4,"",IF($E4=1,EOMONTH(EDATE(Bonds!$I4,6*(25-1)),0),EDATE(Bonds!$I4,6*(25-1)))) | AE4: =IF(26>$D4,"",IF($E4=1,EOMONTH(EDATE(Bonds!$I4,6*(26-1)),0),EDATE(Bonds!$I4,6*(26-1)))) | AF4: =IF(27>$D4,"",IF($E4=1,EOMONTH(EDATE(Bonds!$I4,6*(27-1)),0),EDATE(Bonds!$I4,6*(27-1)))) | AG4: =IF(28>$D4,"",IF($E4=1,EOMONTH(EDATE(Bonds!$I4,6*(28-1)),0),EDATE(Bonds!$I4,6*(28-1)))) | AH4: =IF(29>$D4,"",IF($E4=1,EOMONTH(EDATE(Bonds!$I4,6*(29-1)),0),EDATE(Bonds!$I4,6*(29-1)))) | AI4: =IF(30>$D4,"",IF($E4=1,EOMONTH(EDATE(Bonds!$I4,6*(30-1)),0),EDATE(Bonds!$I4,6*(30-1)))) | AJ4: =IF(31>$D4,"",IF($E4=1,EOMONTH(EDATE(Bonds!$I4,6*(31-1)),0),EDATE(Bonds!$I4,6*(31-1)))) | AK4: =IF(32>$D4,"",IF($E4=1,EOMONTH(EDATE(Bonds!$I4,6*(32-1)),0),EDATE(Bonds!$I4,6*(32-1)))) | AL4: =IF(33>$D4,"",IF($E4=1,EOMONTH(EDATE(Bonds!$I4,6*(33-1)),0),EDATE(Bonds!$I4,6*(33-1)))) | AM4: =IF(34>$D4,"",IF($E4=1,EOMONTH(EDATE(Bonds!$I4,6*(34-1)),0),EDATE(Bonds!$I4,6*(34-1)))) | AN4: =IF(35>$D4,"",IF($E4=1,EOMONTH(EDATE(Bonds!$I4,6*(35-1)),0),EDATE(Bonds!$I4,6*(35-1)))) | AO4: =IF(36>$D4,"",IF($E4=1,EOMONTH(EDATE(Bonds!$I4,6*(36-1)),0),EDATE(Bonds!$I4,6*(36-1)))) | AP4: =IF(37>$D4,"",IF($E4=1,EOMONTH(EDATE(Bonds!$I4,6*(37-1)),0),EDATE(Bonds!$I4,6*(37-1)))) | AQ4: =IF(38>$D4,"",IF($E4=1,EOMONTH(EDATE(Bonds!$I4,6*(38-1)),0),EDATE(Bonds!$I4,6*(38-1)))) | AR4: =IF(39>$D4,"",IF($E4=1,EOMONTH(EDATE(Bonds!$I4,6*(39-1)),0),EDATE(Bonds!$I4,6*(39-1)))) | AS4: =IF(40>$D4,"",IF($E4=1,EOMONTH(EDATE(Bonds!$I4,6*(40-1)),0),EDATE(Bonds!$I4,6*(40-1)))) | AT4: =IF(41>$D4,"",IF($E4=1,EOMONTH(EDATE(Bonds!$I4,6*(41-1)),0),EDATE(Bonds!$I4,6*(41-1)))) | AU4: =IF(42>$D4,"",IF($E4=1,EOMONTH(EDATE(Bonds!$I4,6*(42-1)),0),EDATE(Bonds!$I4,6*(42-1)))) | AV4: =IF(43>$D4,"",IF($E4=1,EOMONTH(EDATE(Bonds!$I4,6*(43-1)),0),EDATE(Bonds!$I4,6*(43-1)))) | AW4: =IF(44>$D4,"",IF($E4=1,EOMONTH(EDATE(Bonds!$I4,6*(44-1)),0),EDATE(Bonds!$I4,6*(44-1)))) | AX4: =IF(45>$D4,"",IF($E4=1,EOMONTH(EDATE(Bonds!$I4,6*(45-1)),0),EDATE(Bonds!$I4,6*(45-1)))) | AY4: =IF(46>$D4,"",IF($E4=1,EOMONTH(EDATE(Bonds!$I4,6*(46-1)),0),EDATE(Bonds!$I4,6*(46-1)))) | AZ4: =IF(47>$D4,"",IF($E4=1,EOMONTH(EDATE(Bonds!$I4,6*(47-1)),0),EDATE(Bonds!$I4,6*(47-1)))) | BA4: =IF(48>$D4,"",IF($E4=1,EOMONTH(EDATE(Bonds!$I4,6*(48-1)),0),EDATE(Bonds!$I4,6*(48-1)))) | BB4: =IF(49>$D4,"",IF($E4=1,EOMONTH(EDATE(Bonds!$I4,6*(49-1)),0),EDATE(Bonds!$I4,6*(49-1)))) | BC4: =IF(50>$D4,"",IF($E4=1,EOMONTH(EDATE(Bonds!$I4,6*(50-1)),0),EDATE(Bonds!$I4,6*(50-1)))) | BD4: =IF(51>$D4,"",IF($E4=1,EOMONTH(EDATE(Bonds!$I4,6*(51-1)),0),EDATE(Bonds!$I4,6*(51-1)))) | BE4: =IF(52>$D4,"",IF($E4=1,EOMONTH(EDATE(Bonds!$I4,6*(52-1)),0),EDATE(Bonds!$I4,6*(52-1)))) | BF4: =IF(53>$D4,"",IF($E4=1,EOMONTH(EDATE(Bonds!$I4,6*(53-1)),0),EDATE(Bonds!$I4,6*(53-1)))) | BG4: =IF(54>$D4,"",IF($E4=1,EOMONTH(EDATE(Bonds!$I4,6*(54-1)),0),EDATE(Bonds!$I4,6*(54-1)))) | BH4: =IF(55>$D4,"",IF($E4=1,EOMONTH(EDATE(Bonds!$I4,6*(55-1)),0),EDATE(Bonds!$I4,6*(55-1)))) | BI4: =IF(56>$D4,"",IF($E4=1,EOMONTH(EDATE(Bonds!$I4,6*(56-1)),0),EDATE(Bonds!$I4,6*(56-1)))) | BJ4: =IF(57>$D4,"",IF($E4=1,EOMONTH(EDATE(Bonds!$I4,6*(57-1)),0),EDATE(Bonds!$I4,6*(57-1)))) | BK4: =IF(58>$D4,"",IF($E4=1,EOMONTH(EDATE(Bonds!$I4,6*(58-1)),0),EDATE(Bonds!$I4,6*(58-1)))) | BL4: =IF(59>$D4,"",IF($E4=1,EOMONTH(EDATE(Bonds!$I4,6*(59-1)),0),EDATE(Bonds!$I4,6*(59-1)))) | BM4: =IF(60>$D4,"",IF($E4=1,EOMONTH(EDATE(Bonds!$I4,6*(60-1)),0),EDATE(Bonds!$I4,6*(60-1)))) | BO4: =IF(F4="","",Sv_beta0+Sv_beta1*(1-EXP(-((F4-Settle)/365)/Sv_tau1))/(((F4-Settle)/365)/Sv_tau1)+Sv_beta2*((1-EXP(-((F4-Settle)/365)/Sv_tau1))/(((F4-Settle)/365)/Sv_tau1)-EXP(-((F4-Settle)/365)/Sv_tau1))+Sv_beta3*((1-EXP(-((F4-Settle)/365)/Sv_tau2))/(((F4-Settle)/365)/Sv_tau2)-EXP(-((F4-Settle)/365)/Sv_tau2))) -> 0.036418324 | BP4: =IF(G4="","",Sv_beta0+Sv_beta1*(1-EXP(-((G4-Settle)/365)/Sv_tau1))/(((G4-Settle)/365)/Sv_tau1)+Sv_beta2*((1-EXP(-((G4-Settle)/365)/Sv_tau1))/(((G4-Settle)/365)/Sv_tau1)-EXP(-((G4-Settle)/365)/Sv_tau1))+Sv_beta3*((1-EXP(-((G4-Settle)/365)/Sv_tau2))/(((G4-Settle)/365)/Sv_tau2)-EXP(-((G4-Settle)/365)/Sv_tau2))) | BQ4: =IF(H4="","",Sv_beta0+Sv_beta1*(1-EXP(-((H4-Settle)/365)/Sv_tau1))/(((H4-Settle)/365)/Sv_tau1)+Sv_beta2*((1-EXP(-((H4-Settle)/365)/Sv_tau1))/(((H4-Settle)/365)/Sv_tau1)-EXP(-((H4-Settle)/365)/Sv_tau1))+Sv_beta3*((1-EXP(-((H4-Settle)/365)/Sv_tau2))/(((H4-Settle)/365)/Sv_tau2)-EXP(-((H4-Settle)/365)/Sv_tau2))) | BR4: =IF(I4="","",Sv_beta0+Sv_beta1*(1-EXP(-((I4-Settle)/365)/Sv_tau1))/(((I4-Settle)/365)/Sv_tau1)+Sv_beta2*((1-EXP(-((I4-Settle)/365)/Sv_tau1))/(((I4-Settle)/365)/Sv_tau1)-EXP(-((I4-Settle)/365)/Sv_tau1))+Sv_beta3*((1-EXP(-((I4-Settle)/365)/Sv_tau2))/(((I4-Settle)/365)/Sv_tau2)-EXP(-((I4-Settle)/365)/Sv_tau2))) | BS4: =IF(J4="","",Sv_beta0+Sv_beta1*(1-EXP(-((J4-Settle)/365)/Sv_tau1))/(((J4-Settle)/365)/Sv_tau1)+Sv_beta2*((1-EXP(-((J4-Settle)/365)/Sv_tau1))/(((J4-Settle)/365)/Sv_tau1)-EXP(-((J4-Settle)/365)/Sv_tau1))+Sv_beta3*((1-EXP(-((J4-Settle)/365)/Sv_tau2))/(((J4-Settle)/365)/Sv_tau2)-EXP(-((J4-Settle)/365)/Sv_tau2))) | BT4: =IF(K4="","",Sv_beta0+Sv_beta1*(1-EXP(-((K4-Settle)/365)/Sv_tau1))/(((K4-Settle)/365)/Sv_tau1)+Sv_beta2*((1-EXP(-((K4-Settle)/365)/Sv_tau1))/(((K4-Settle)/365)/Sv_tau1)-EXP(-((K4-Settle)/365)/Sv_tau1))+Sv_beta3*((1-EXP(-((K4-Settle)/365)/Sv_tau2))/(((K4-Settle)/365)/Sv_tau2)-EXP(-((K4-Settle)/365)/Sv_tau2))) | BU4: =IF(L4="","",Sv_beta0+Sv_beta1*(1-EXP(-((L4-Settle)/365)/Sv_tau1))/(((L4-Settle)/365)/Sv_tau1)+Sv_beta2*((1-EXP(-((L4-Settle)/365)/Sv_tau1))/(((L4-Settle)/365)/Sv_tau1)-EXP(-((L4-Settle)/365)/Sv_tau1))+Sv_beta3*((1-EXP(-((L4-Settle)/365)/Sv_tau2))/(((L4-Settle)/365)/Sv_tau2)-EXP(-((L4-Settle)/365)/Sv_tau2))) | BV4: =IF(M4="","",Sv_beta0+Sv_beta1*(1-EXP(-((M4-Settle)/365)/Sv_tau1))/(((M4-Settle)/365)/Sv_tau1)+Sv_beta2*((1-EXP(-((M4-Settle)/365)/Sv_tau1))/(((M4-Settle)/365)/Sv_tau1)-EXP(-((M4-Settle)/365)/Sv_tau1))+Sv_beta3*((1-EXP(-((M4-Settle)/365)/Sv_tau2))/(((M4-Settle)/365)/Sv_tau2)-EXP(-((M4-Settle)/365)/Sv_tau2))) | ... DV4: =IF(BM4="","",Sv_beta0+Sv_beta1*(1-EXP(-((BM4-Settle)/365)/Sv_tau1))/(((BM4-Settle)/365)/Sv_tau1)+Sv_beta2*((1-EXP(-((BM4-Settle)/365)/Sv_tau1))/(((BM4-Settle)/365)/Sv_tau1)-EXP(-((BM4-Settle)/365)/Sv_tau1))+Sv_beta3*((1-EXP(-((BM4-Settle)/365)/Sv_tau2))/(((BM4-Settle)/365)/Sv_tau2)-EXP(-((BM4-Settle)/365)/Sv_tau2))) | DX4: =IF(F4="",0,($C4/2+IF(1=$D4,100,0))*EXP(-BO4*((F4-Settle)/365))) -> 102.24107 | DY4: =IF(G4="",0,($C4/2+IF(2=$D4,100,0))*EXP(-BP4*((G4-Settle)/365))) -> 0 | DZ4: =IF(H4="",0,($C4/2+IF(3=$D4,100,0))*EXP(-BQ4*((H4-Settle)/365))) -> 0 | EA4: =IF(I4="",0,($C4/2+IF(4=$D4,100,0))*EXP(-BR4*((I4-Settle)/365))) -> 0 | EB4: =IF(J4="",0,($C4/2+IF(5=$D4,100,0))*EXP(-BS4*((J4-Settle)/365))) -> 0 | EC4: =IF(K4="",0,($C4/2+IF(6=$D4,100,0))*EXP(-BT4*((K4-Settle)/365))) -> 0 | ED4: =IF(L4="",0,($C4/2+IF(7=$D4,100,0))*EXP(-BU4*((L4-Settle)/365))) -> 0 | EE4: =IF(M4="",0,($C4/2+IF(8=$D4,100,0))*EXP(-BV4*((M4-Settle)/365))) -> 0 | EF4: =IF(N4="",0,($C4/2+IF(9=$D4,100,0))*EXP(-BW4*((N4-Settle)/365))) -> 0 | EG4: =IF(O4="",0,($C4/2+IF(10=$D4,100,0))*EXP(-BX4*((O4-Settle)/365))) -> 0 | EH4: =IF(P4="",0,($C4/2+IF(11=$D4,100,0))*EXP(-BY4*((P4-Settle)/365))) -> 0 | EI4: =IF(Q4="",0,($C4/2+IF(12=$D4,100,0))*EXP(-BZ4*((Q4-Settle)/365))) -> 0 | EJ4: =IF(R4="",0,($C4/2+IF(13=$D4,100,0))*EXP(-CA4*((R4-Settle)/365))) -> 0 | EK4: =IF(S4="",0,($C4/2+IF(14=$D4,100,0))*EXP(-CB4*((S4-Settle)/365))) -> 0 | EL4: =IF(T4="",0,($C4/2+IF(15=$D4,100,0))*EXP(-CC4*((T4-Settle)/365))) -> 0 | EM4: =IF(U4="",0,($C4/2+IF(16=$D4,100,0))*EXP(-CD4*((U4-Settle)/365))) -> 0 | EN4: =IF(V4="",0,($C4/2+IF(17=$D4,100,0))*EXP(-CE4*((V4-Settle)/365))) -> 0 | EO4: =IF(W4="",0,($C4/2+IF(18=$D4,100,0))*EXP(-CF4*((W4-Settle)/365))) -> 0 | EP4: =IF(X4="",0,($C4/2+IF(19=$D4,100,0))*EXP(-CG4*((X4-Settle)/365))) -> 0 | EQ4: =IF(Y4="",0,($C4/2+IF(20=$D4,100,0))*EXP(-CH4*((Y4-Settle)/365))) -> 0 | ER4: =IF(Z4="",0,($C4/2+IF(21=$D4,100,0))*EXP(-CI4*((Z4-Settle)/365))) -> 0 | ES4: =IF(AA4="",0,($C4/2+IF(22=$D4,100,0))*EXP(-CJ4*((AA4-Settle)/365))) -> 0 | ET4: =IF(AB4="",0,($C4/2+IF(23=$D4,100,0))*EXP(-CK4*((AB4-Settle)/365))) -> 0 | EU4: =IF(AC4="",0,($C4/2+IF(24=$D4,100,0))*EXP(-CL4*((AC4-Settle)/365))) -> 0 | EV4: =IF(AD4="",0,($C4/2+IF(25=$D4,100,0))*EXP(-CM4*((AD4-Settle)/365))) -> 0 | EW4: =IF(AE4="",0,($C4/2+IF(26=$D4,100,0))*EXP(-CN4*((AE4-Settle)/365))) -> 0 | EX4: =IF(AF4="",0,($C4/2+IF(27=$D4,100,0))*EXP(-CO4*((AF4-Settle)/365))) -> 0 | EY4: =IF(AG4="",0,($C4/2+IF(28=$D4,100,0))*EXP(-CP4*((AG4-Settle)/365))) -> 0 | EZ4: =IF(AH4="",0,($C4/2+IF(29=$D4,100,0))*EXP(-CQ4*((AH4-Settle)/365))) -> 0 | FA4: =IF(AI4="",0,($C4/2+IF(30=$D4,100,0))*EXP(-CR4*((AI4-Settle)/365))) -> 0 | FB4: =IF(AJ4="",0,($C4/2+IF(31=$D4,100,0))*EXP(-CS4*((AJ4-Settle)/365))) -> 0 | FC4: =IF(AK4="",0,($C4/2+IF(32=$D4,100,0))*EXP(-CT4*((AK4-Settle)/365))) -> 0 | FD4: =IF(AL4="",0,($C4/2+IF(33=$D4,100,0))*EXP(-CU4*((AL4-Settle)/365))) -> 0 | FE4: =IF(AM4="",0,($C4/2+IF(34=$D4,100,0))*EXP(-CV4*((AM4-Settle)/365))) -> 0 | FF4: =IF(AN4="",0,($C4/2+IF(35=$D4,100,0))*EXP(-CW4*((AN4-Settle)/365))) -> 0 | FG4: =IF(AO4="",0,($C4/2+IF(36=$D4,100,0))*EXP(-CX4*((AO4-Settle)/365))) -> 0 | FH4: =IF(AP4="",0,($C4/2+IF(37=$D4,100,0))*EXP(-CY4*((AP4-Settle)/365))) -> 0 | FI4: =IF(AQ4="",0,($C4/2+IF(38=$D4,100,0))*EXP(-CZ4*((AQ4-Settle)/365))) -> 0 | FJ4: =IF(AR4="",0,($C4/2+IF(39=$D4,100,0))*EXP(-DA4*((AR4-Settle)/365))) -> 0 | FK4: =IF(AS4="",0,($C4/2+IF(40=$D4,100,0))*EXP(-DB4*((AS4-Settle)/365))) -> 0 | FL4: =IF(AT4="",0,($C4/2+IF(41=$D4,100,0))*EXP(-DC4*((AT4-Settle)/365))) -> 0 | FM4: =IF(AU4="",0,($C4/2+IF(42=$D4,100,0))*EXP(-DD4*((AU4-Settle)/365))) -> 0 | FN4: =IF(AV4="",0,($C4/2+IF(43=$D4,100,0))*EXP(-DE4*((AV4-Settle)/365))) -> 0 | FO4: =IF(AW4="",0,($C4/2+IF(44=$D4,100,0))*EXP(-DF4*((AW4-Settle)/365))) -> 0 | FP4: =IF(AX4="",0,($C4/2+IF(45=$D4,100,0))*EXP(-DG4*((AX4-Settle)/365))) -> 0 | FQ4: =IF(AY4="",0,($C4/2+IF(46=$D4,100,0))*EXP(-DH4*((AY4-Settle)/365))) -> 0 | FR4: =IF(AZ4="",0,($C4/2+IF(47=$D4,100,0))*EXP(-DI4*((AZ4-Settle)/365))) -> 0 | FS4: =IF(BA4="",0,($C4/2+IF(48=$D4,100,0))*EXP(-DJ4*((BA4-Settle)/365))) -> 0 | FT4: =IF(BB4="",0,($C4/2+IF(49=$D4,100,0))*EXP(-DK4*((BB4-Settle)/365))) -> 0 | FU4: =IF(BC4="",0,($C4/2+IF(50=$D4,100,0))*EXP(-DL4*((BC4-Settle)/365))) -> 0 | FV4: =IF(BD4="",0,($C4/2+IF(51=$D4,100,0))*EXP(-DM4*((BD4-Settle)/365))) -> 0 | FW4: =IF(BE4="",0,($C4/2+IF(52=$D4,100,0))*EXP(-DN4*((BE4-Settle)/365))) -> 0 | FX4: =IF(BF4="",0,($C4/2+IF(53=$D4,100,0))*EXP(-DO4*((BF4-Settle)/365))) -> 0 | FY4: =IF(BG4="",0,($C4/2+IF(54=$D4,100,0))*EXP(-DP4*((BG4-Settle)/365))) -> 0 | FZ4: =IF(BH4="",0,($C4/2+IF(55=$D4,100,0))*EXP(-DQ4*((BH4-Settle)/365))) -> 0 | GA4: =IF(BI4="",0,($C4/2+IF(56=$D4,100,0))*EXP(-DR4*((BI4-Settle)/365))) -> 0 | GB4: =IF(BJ4="",0,($C4/2+IF(57=$D4,100,0))*EXP(-DS4*((BJ4-Settle)/365))) -> 0 | GC4: =IF(BK4="",0,($C4/2+IF(58=$D4,100,0))*EXP(-DT4*((BK4-Settle)/365))) -> 0 | GD4: =IF(BL4="",0,($C4/2+IF(59=$D4,100,0))*EXP(-DU4*((BL4-Settle)/365))) -> 0 | GE4: =IF(BM4="",0,($C4/2+IF(60=$D4,100,0))*EXP(-DV4*((BM4-Settle)/365))) -> 0
A5: 2 | B5: =Bonds!B5 -> 46295 | C5: =Bonds!C5 -> 0.875 | D5: =Bonds!Q5 -> 1 | E5: =IF(DAY(B5)=DAY(EOMONTH(B5,0)),1,0) -> 1 | F5: =IF(1>$D5,"",IF($E5=1,EOMONTH(EDATE(Bonds!$I5,6*(1-1)),0),EDATE(Bonds!$I5,6*(1-1)))) -> 46295 | G5: =IF(2>$D5,"",IF($E5=1,EOMONTH(EDATE(Bonds!$I5,6*(2-1)),0),EDATE(Bonds!$I5,6*(2-1)))) | H5: =IF(3>$D5,"",IF($E5=1,EOMONTH(EDATE(Bonds!$I5,6*(3-1)),0),EDATE(Bonds!$I5,6*(3-1)))) | I5: =IF(4>$D5,"",IF($E5=1,EOMONTH(EDATE(Bonds!$I5,6*(4-1)),0),EDATE(Bonds!$I5,6*(4-1)))) | J5: =IF(5>$D5,"",IF($E5=1,EOMONTH(EDATE(Bonds!$I5,6*(5-1)),0),EDATE(Bonds!$I5,6*(5-1)))) | K5: =IF(6>$D5,"",IF($E5=1,EOMONTH(EDATE(Bonds!$I5,6*(6-1)),0),EDATE(Bonds!$I5,6*(6-1)))) | L5: =IF(7>$D5,"",IF($E5=1,EOMONTH(EDATE(Bonds!$I5,6*(7-1)),0),EDATE(Bonds!$I5,6*(7-1)))) | M5: =IF(8>$D5,"",IF($E5=1,EOMONTH(EDATE(Bonds!$I5,6*(8-1)),0),EDATE(Bonds!$I5,6*(8-1)))) | N5: =IF(9>$D5,"",IF($E5=1,EOMONTH(EDATE(Bonds!$I5,6*(9-1)),0),EDATE(Bonds!$I5,6*(9-1)))) | O5: =IF(10>$D5,"",IF($E5=1,EOMONTH(EDATE(Bonds!$I5,6*(10-1)),0),EDATE(Bonds!$I5,6*(10-1)))) | P5: =IF(11>$D5,"",IF($E5=1,EOMONTH(EDATE(Bonds!$I5,6*(11-1)),0),EDATE(Bonds!$I5,6*(11-1)))) | Q5: =IF(12>$D5,"",IF($E5=1,EOMONTH(EDATE(Bonds!$I5,6*(12-1)),0),EDATE(Bonds!$I5,6*(12-1)))) | R5: =IF(13>$D5,"",IF($E5=1,EOMONTH(EDATE(Bonds!$I5,6*(13-1)),0),EDATE(Bonds!$I5,6*(13-1)))) | S5: =IF(14>$D5,"",IF($E5=1,EOMONTH(EDATE(Bonds!$I5,6*(14-1)),0),EDATE(Bonds!$I5,6*(14-1)))) | T5: =IF(15>$D5,"",IF($E5=1,EOMONTH(EDATE(Bonds!$I5,6*(15-1)),0),EDATE(Bonds!$I5,6*(15-1)))) | U5: =IF(16>$D5,"",IF($E5=1,EOMONTH(EDATE(Bonds!$I5,6*(16-1)),0),EDATE(Bonds!$I5,6*(16-1)))) | V5: =IF(17>$D5,"",IF($E5=1,EOMONTH(EDATE(Bonds!$I5,6*(17-1)),0),EDATE(Bonds!$I5,6*(17-1)))) | W5: =IF(18>$D5,"",IF($E5=1,EOMONTH(EDATE(Bonds!$I5,6*(18-1)),0),EDATE(Bonds!$I5,6*(18-1)))) | X5: =IF(19>$D5,"",IF($E5=1,EOMONTH(EDATE(Bonds!$I5,6*(19-1)),0),EDATE(Bonds!$I5,6*(19-1)))) | Y5: =IF(20>$D5,"",IF($E5=1,EOMONTH(EDATE(Bonds!$I5,6*(20-1)),0),EDATE(Bonds!$I5,6*(20-1)))) | Z5: =IF(21>$D5,"",IF($E5=1,EOMONTH(EDATE(Bonds!$I5,6*(21-1)),0),EDATE(Bonds!$I5,6*(21-1)))) | AA5: =IF(22>$D5,"",IF($E5=1,EOMONTH(EDATE(Bonds!$I5,6*(22-1)),0),EDATE(Bonds!$I5,6*(22-1)))) | AB5: =IF(23>$D5,"",IF($E5=1,EOMONTH(EDATE(Bonds!$I5,6*(23-1)),0),EDATE(Bonds!$I5,6*(23-1)))) | AC5: =IF(24>$D5,"",IF($E5=1,EOMONTH(EDATE(Bonds!$I5,6*(24-1)),0),EDATE(Bonds!$I5,6*(24-1)))) | AD5: =IF(25>$D5,"",IF($E5=1,EOMONTH(EDATE(Bonds!$I5,6*(25-1)),0),EDATE(Bonds!$I5,6*(25-1)))) | AE5: =IF(26>$D5,"",IF($E5=1,EOMONTH(EDATE(Bonds!$I5,6*(26-1)),0),EDATE(Bonds!$I5,6*(26-1)))) | AF5: =IF(27>$D5,"",IF($E5=1,EOMONTH(EDATE(Bonds!$I5,6*(27-1)),0),EDATE(Bonds!$I5,6*(27-1)))) | AG5: =IF(28>$D5,"",IF($E5=1,EOMONTH(EDATE(Bonds!$I5,6*(28-1)),0),EDATE(Bonds!$I5,6*(28-1)))) | AH5: =IF(29>$D5,"",IF($E5=1,EOMONTH(EDATE(Bonds!$I5,6*(29-1)),0),EDATE(Bonds!$I5,6*(29-1)))) | AI5: =IF(30>$D5,"",IF($E5=1,EOMONTH(EDATE(Bonds!$I5,6*(30-1)),0),EDATE(Bonds!$I5,6*(30-1)))) | AJ5: =IF(31>$D5,"",IF($E5=1,EOMONTH(EDATE(Bonds!$I5,6*(31-1)),0),EDATE(Bonds!$I5,6*(31-1)))) | AK5: =IF(32>$D5,"",IF($E5=1,EOMONTH(EDATE(Bonds!$I5,6*(32-1)),0),EDATE(Bonds!$I5,6*(32-1)))) | AL5: =IF(33>$D5,"",IF($E5=1,EOMONTH(EDATE(Bonds!$I5,6*(33-1)),0),EDATE(Bonds!$I5,6*(33-1)))) | AM5: =IF(34>$D5,"",IF($E5=1,EOMONTH(EDATE(Bonds!$I5,6*(34-1)),0),EDATE(Bonds!$I5,6*(34-1)))) | AN5: =IF(35>$D5,"",IF($E5=1,EOMONTH(EDATE(Bonds!$I5,6*(35-1)),0),EDATE(Bonds!$I5,6*(35-1)))) | AO5: =IF(36>$D5,"",IF($E5=1,EOMONTH(EDATE(Bonds!$I5,6*(36-1)),0),EDATE(Bonds!$I5,6*(36-1)))) | AP5: =IF(37>$D5,"",IF($E5=1,EOMONTH(EDATE(Bonds!$I5,6*(37-1)),0),EDATE(Bonds!$I5,6*(37-1)))) | AQ5: =IF(38>$D5,"",IF($E5=1,EOMONTH(EDATE(Bonds!$I5,6*(38-1)),0),EDATE(Bonds!$I5,6*(38-1)))) | AR5: =IF(39>$D5,"",IF($E5=1,EOMONTH(EDATE(Bonds!$I5,6*(39-1)),0),EDATE(Bonds!$I5,6*(39-1)))) | AS5: =IF(40>$D5,"",IF($E5=1,EOMONTH(EDATE(Bonds!$I5,6*(40-1)),0),EDATE(Bonds!$I5,6*(40-1)))) | AT5: =IF(41>$D5,"",IF($E5=1,EOMONTH(EDATE(Bonds!$I5,6*(41-1)),0),EDATE(Bonds!$I5,6*(41-1)))) | AU5: =IF(42>$D5,"",IF($E5=1,EOMONTH(EDATE(Bonds!$I5,6*(42-1)),0),EDATE(Bonds!$I5,6*(42-1)))) | AV5: =IF(43>$D5,"",IF($E5=1,EOMONTH(EDATE(Bonds!$I5,6*(43-1)),0),EDATE(Bonds!$I5,6*(43-1)))) | AW5: =IF(44>$D5,"",IF($E5=1,EOMONTH(EDATE(Bonds!$I5,6*(44-1)),0),EDATE(Bonds!$I5,6*(44-1)))) | AX5: =IF(45>$D5,"",IF($E5=1,EOMONTH(EDATE(Bonds!$I5,6*(45-1)),0),EDATE(Bonds!$I5,6*(45-1)))) | AY5: =IF(46>$D5,"",IF($E5=1,EOMONTH(EDATE(Bonds!$I5,6*(46-1)),0),EDATE(Bonds!$I5,6*(46-1)))) | AZ5: =IF(47>$D5,"",IF($E5=1,EOMONTH(EDATE(Bonds!$I5,6*(47-1)),0),EDATE(Bonds!$I5,6*(47-1)))) | BA5: =IF(48>$D5,"",IF($E5=1,EOMONTH(EDATE(Bonds!$I5,6*(48-1)),0),EDATE(Bonds!$I5,6*(48-1)))) | BB5: =IF(49>$D5,"",IF($E5=1,EOMONTH(EDATE(Bonds!$I5,6*(49-1)),0),EDATE(Bonds!$I5,6*(49-1)))) | BC5: =IF(50>$D5,"",IF($E5=1,EOMONTH(EDATE(Bonds!$I5,6*(50-1)),0),EDATE(Bonds!$I5,6*(50-1)))) | BD5: =IF(51>$D5,"",IF($E5=1,EOMONTH(EDATE(Bonds!$I5,6*(51-1)),0),EDATE(Bonds!$I5,6*(51-1)))) | BE5: =IF(52>$D5,"",IF($E5=1,EOMONTH(EDATE(Bonds!$I5,6*(52-1)),0),EDATE(Bonds!$I5,6*(52-1)))) | BF5: =IF(53>$D5,"",IF($E5=1,EOMONTH(EDATE(Bonds!$I5,6*(53-1)),0),EDATE(Bonds!$I5,6*(53-1)))) | BG5: =IF(54>$D5,"",IF($E5=1,EOMONTH(EDATE(Bonds!$I5,6*(54-1)),0),EDATE(Bonds!$I5,6*(54-1)))) | BH5: =IF(55>$D5,"",IF($E5=1,EOMONTH(EDATE(Bonds!$I5,6*(55-1)),0),EDATE(Bonds!$I5,6*(55-1)))) | BI5: =IF(56>$D5,"",IF($E5=1,EOMONTH(EDATE(Bonds!$I5,6*(56-1)),0),EDATE(Bonds!$I5,6*(56-1)))) | BJ5: =IF(57>$D5,"",IF($E5=1,EOMONTH(EDATE(Bonds!$I5,6*(57-1)),0),EDATE(Bonds!$I5,6*(57-1)))) | BK5: =IF(58>$D5,"",IF($E5=1,EOMONTH(EDATE(Bonds!$I5,6*(58-1)),0),EDATE(Bonds!$I5,6*(58-1)))) | BL5: =IF(59>$D5,"",IF($E5=1,EOMONTH(EDATE(Bonds!$I5,6*(59-1)),0),EDATE(Bonds!$I5,6*(59-1)))) | BM5: =IF(60>$D5,"",IF($E5=1,EOMONTH(EDATE(Bonds!$I5,6*(60-1)),0),EDATE(Bonds!$I5,6*(60-1)))) | BO5: =IF(F5="","",Sv_beta0+Sv_beta1*(1-EXP(-((F5-Settle)/365)/Sv_tau1))/(((F5-Settle)/365)/Sv_tau1)+Sv_beta2*((1-EXP(-((F5-Settle)/365)/Sv_tau1))/(((F5-Settle)/365)/Sv_tau1)-EXP(-((F5-Settle)/365)/Sv_tau1))+Sv_beta3*((1-EXP(-((F5-Settle)/365)/Sv_tau2))/(((F5-Settle)/365)/Sv_tau2)-EXP(-((F5-Settle)/365)/Sv_tau2))) -> 0.036715304 | BP5: =IF(G5="","",Sv_beta0+Sv_beta1*(1-EXP(-((G5-Settle)/365)/Sv_tau1))/(((G5-Settle)/365)/Sv_tau1)+Sv_beta2*((1-EXP(-((G5-Settle)/365)/Sv_tau1))/(((G5-Settle)/365)/Sv_tau1)-EXP(-((G5-Settle)/365)/Sv_tau1))+Sv_beta3*((1-EXP(-((G5-Settle)/365)/Sv_tau2))/(((G5-Settle)/365)/Sv_tau2)-EXP(-((G5-Settle)/365)/Sv_tau2))) | BQ5: =IF(H5="","",Sv_beta0+Sv_beta1*(1-EXP(-((H5-Settle)/365)/Sv_tau1))/(((H5-Settle)/365)/Sv_tau1)+Sv_beta2*((1-EXP(-((H5-Settle)/365)/Sv_tau1))/(((H5-Settle)/365)/Sv_tau1)-EXP(-((H5-Settle)/365)/Sv_tau1))+Sv_beta3*((1-EXP(-((H5-Settle)/365)/Sv_tau2))/(((H5-Settle)/365)/Sv_tau2)-EXP(-((H5-Settle)/365)/Sv_tau2))) | BR5: =IF(I5="","",Sv_beta0+Sv_beta1*(1-EXP(-((I5-Settle)/365)/Sv_tau1))/(((I5-Settle)/365)/Sv_tau1)+Sv_beta2*((1-EXP(-((I5-Settle)/365)/Sv_tau1))/(((I5-Settle)/365)/Sv_tau1)-EXP(-((I5-Settle)/365)/Sv_tau1))+Sv_beta3*((1-EXP(-((I5-Settle)/365)/Sv_tau2))/(((I5-Settle)/365)/Sv_tau2)-EXP(-((I5-Settle)/365)/Sv_tau2))) | BS5: =IF(J5="","",Sv_beta0+Sv_beta1*(1-EXP(-((J5-Settle)/365)/Sv_tau1))/(((J5-Settle)/365)/Sv_tau1)+Sv_beta2*((1-EXP(-((J5-Settle)/365)/Sv_tau1))/(((J5-Settle)/365)/Sv_tau1)-EXP(-((J5-Settle)/365)/Sv_tau1))+Sv_beta3*((1-EXP(-((J5-Settle)/365)/Sv_tau2))/(((J5-Settle)/365)/Sv_tau2)-EXP(-((J5-Settle)/365)/Sv_tau2))) | BT5: =IF(K5="","",Sv_beta0+Sv_beta1*(1-EXP(-((K5-Settle)/365)/Sv_tau1))/(((K5-Settle)/365)/Sv_tau1)+Sv_beta2*((1-EXP(-((K5-Settle)/365)/Sv_tau1))/(((K5-Settle)/365)/Sv_tau1)-EXP(-((K5-Settle)/365)/Sv_tau1))+Sv_beta3*((1-EXP(-((K5-Settle)/365)/Sv_tau2))/(((K5-Settle)/365)/Sv_tau2)-EXP(-((K5-Settle)/365)/Sv_tau2))) | BU5: =IF(L5="","",Sv_beta0+Sv_beta1*(1-EXP(-((L5-Settle)/365)/Sv_tau1))/(((L5-Settle)/365)/Sv_tau1)+Sv_beta2*((1-EXP(-((L5-Settle)/365)/Sv_tau1))/(((L5-Settle)/365)/Sv_tau1)-EXP(-((L5-Settle)/365)/Sv_tau1))+Sv_beta3*((1-EXP(-((L5-Settle)/365)/Sv_tau2))/(((L5-Settle)/365)/Sv_tau2)-EXP(-((L5-Settle)/365)/Sv_tau2))) | BV5: =IF(M5="","",Sv_beta0+Sv_beta1*(1-EXP(-((M5-Settle)/365)/Sv_tau1))/(((M5-Settle)/365)/Sv_tau1)+Sv_beta2*((1-EXP(-((M5-Settle)/365)/Sv_tau1))/(((M5-Settle)/365)/Sv_tau1)-EXP(-((M5-Settle)/365)/Sv_tau1))+Sv_beta3*((1-EXP(-((M5-Settle)/365)/Sv_tau2))/(((M5-Settle)/365)/Sv_tau2)-EXP(-((M5-Settle)/365)/Sv_tau2))) | ... DV5: =IF(BM5="","",Sv_beta0+Sv_beta1*(1-EXP(-((BM5-Settle)/365)/Sv_tau1))/(((BM5-Settle)/365)/Sv_tau1)+Sv_beta2*((1-EXP(-((BM5-Settle)/365)/Sv_tau1))/(((BM5-Settle)/365)/Sv_tau1)-EXP(-((BM5-Settle)/365)/Sv_tau1))+Sv_beta3*((1-EXP(-((BM5-Settle)/365)/Sv_tau2))/(((BM5-Settle)/365)/Sv_tau2)-EXP(-((BM5-Settle)/365)/Sv_tau2))) | DX5: =IF(F5="",0,($C5/2+IF(1=$D5,100,0))*EXP(-BO5*((F5-Settle)/365))) -> 100.21548 | DY5: =IF(G5="",0,($C5/2+IF(2=$D5,100,0))*EXP(-BP5*((G5-Settle)/365))) -> 0 | DZ5: =IF(H5="",0,($C5/2+IF(3=$D5,100,0))*EXP(-BQ5*((H5-Settle)/365))) -> 0 | EA5: =IF(I5="",0,($C5/2+IF(4=$D5,100,0))*EXP(-BR5*((I5-Settle)/365))) -> 0 | EB5: =IF(J5="",0,($C5/2+IF(5=$D5,100,0))*EXP(-BS5*((J5-Settle)/365))) -> 0 | EC5: =IF(K5="",0,($C5/2+IF(6=$D5,100,0))*EXP(-BT5*((K5-Settle)/365))) -> 0 | ED5: =IF(L5="",0,($C5/2+IF(7=$D5,100,0))*EXP(-BU5*((L5-Settle)/365))) -> 0 | EE5: =IF(M5="",0,($C5/2+IF(8=$D5,100,0))*EXP(-BV5*((M5-Settle)/365))) -> 0 | EF5: =IF(N5="",0,($C5/2+IF(9=$D5,100,0))*EXP(-BW5*((N5-Settle)/365))) -> 0 | EG5: =IF(O5="",0,($C5/2+IF(10=$D5,100,0))*EXP(-BX5*((O5-Settle)/365))) -> 0 | EH5: =IF(P5="",0,($C5/2+IF(11=$D5,100,0))*EXP(-BY5*((P5-Settle)/365))) -> 0 | EI5: =IF(Q5="",0,($C5/2+IF(12=$D5,100,0))*EXP(-BZ5*((Q5-Settle)/365))) -> 0 | EJ5: =IF(R5="",0,($C5/2+IF(13=$D5,100,0))*EXP(-CA5*((R5-Settle)/365))) -> 0 | EK5: =IF(S5="",0,($C5/2+IF(14=$D5,100,0))*EXP(-CB5*((S5-Settle)/365))) -> 0 | EL5: =IF(T5="",0,($C5/2+IF(15=$D5,100,0))*EXP(-CC5*((T5-Settle)/365))) -> 0 | EM5: =IF(U5="",0,($C5/2+IF(16=$D5,100,0))*EXP(-CD5*((U5-Settle)/365))) -> 0 | EN5: =IF(V5="",0,($C5/2+IF(17=$D5,100,0))*EXP(-CE5*((V5-Settle)/365))) -> 0 | EO5: =IF(W5="",0,($C5/2+IF(18=$D5,100,0))*EXP(-CF5*((W5-Settle)/365))) -> 0 | EP5: =IF(X5="",0,($C5/2+IF(19=$D5,100,0))*EXP(-CG5*((X5-Settle)/365))) -> 0 | EQ5: =IF(Y5="",0,($C5/2+IF(20=$D5,100,0))*EXP(-CH5*((Y5-Settle)/365))) -> 0 | ER5: =IF(Z5="",0,($C5/2+IF(21=$D5,100,0))*EXP(-CI5*((Z5-Settle)/365))) -> 0 | ES5: =IF(AA5="",0,($C5/2+IF(22=$D5,100,0))*EXP(-CJ5*((AA5-Settle)/365))) -> 0 | ET5: =IF(AB5="",0,($C5/2+IF(23=$D5,100,0))*EXP(-CK5*((AB5-Settle)/365))) -> 0 | EU5: =IF(AC5="",0,($C5/2+IF(24=$D5,100,0))*EXP(-CL5*((AC5-Settle)/365))) -> 0 | EV5: =IF(AD5="",0,($C5/2+IF(25=$D5,100,0))*EXP(-CM5*((AD5-Settle)/365))) -> 0 | EW5: =IF(AE5="",0,($C5/2+IF(26=$D5,100,0))*EXP(-CN5*((AE5-Settle)/365))) -> 0 | EX5: =IF(AF5="",0,($C5/2+IF(27=$D5,100,0))*EXP(-CO5*((AF5-Settle)/365))) -> 0 | EY5: =IF(AG5="",0,($C5/2+IF(28=$D5,100,0))*EXP(-CP5*((AG5-Settle)/365))) -> 0 | EZ5: =IF(AH5="",0,($C5/2+IF(29=$D5,100,0))*EXP(-CQ5*((AH5-Settle)/365))) -> 0 | FA5: =IF(AI5="",0,($C5/2+IF(30=$D5,100,0))*EXP(-CR5*((AI5-Settle)/365))) -> 0 | FB5: =IF(AJ5="",0,($C5/2+IF(31=$D5,100,0))*EXP(-CS5*((AJ5-Settle)/365))) -> 0 | FC5: =IF(AK5="",0,($C5/2+IF(32=$D5,100,0))*EXP(-CT5*((AK5-Settle)/365))) -> 0 | FD5: =IF(AL5="",0,($C5/2+IF(33=$D5,100,0))*EXP(-CU5*((AL5-Settle)/365))) -> 0 | FE5: =IF(AM5="",0,($C5/2+IF(34=$D5,100,0))*EXP(-CV5*((AM5-Settle)/365))) -> 0 | FF5: =IF(AN5="",0,($C5/2+IF(35=$D5,100,0))*EXP(-CW5*((AN5-Settle)/365))) -> 0 | FG5: =IF(AO5="",0,($C5/2+IF(36=$D5,100,0))*EXP(-CX5*((AO5-Settle)/365))) -> 0 | FH5: =IF(AP5="",0,($C5/2+IF(37=$D5,100,0))*EXP(-CY5*((AP5-Settle)/365))) -> 0 | FI5: =IF(AQ5="",0,($C5/2+IF(38=$D5,100,0))*EXP(-CZ5*((AQ5-Settle)/365))) -> 0 | FJ5: =IF(AR5="",0,($C5/2+IF(39=$D5,100,0))*EXP(-DA5*((AR5-Settle)/365))) -> 0 | FK5: =IF(AS5="",0,($C5/2+IF(40=$D5,100,0))*EXP(-DB5*((AS5-Settle)/365))) -> 0 | FL5: =IF(AT5="",0,($C5/2+IF(41=$D5,100,0))*EXP(-DC5*((AT5-Settle)/365))) -> 0 | FM5: =IF(AU5="",0,($C5/2+IF(42=$D5,100,0))*EXP(-DD5*((AU5-Settle)/365))) -> 0 | FN5: =IF(AV5="",0,($C5/2+IF(43=$D5,100,0))*EXP(-DE5*((AV5-Settle)/365))) -> 0 | FO5: =IF(AW5="",0,($C5/2+IF(44=$D5,100,0))*EXP(-DF5*((AW5-Settle)/365))) -> 0 | FP5: =IF(AX5="",0,($C5/2+IF(45=$D5,100,0))*EXP(-DG5*((AX5-Settle)/365))) -> 0 | FQ5: =IF(AY5="",0,($C5/2+IF(46=$D5,100,0))*EXP(-DH5*((AY5-Settle)/365))) -> 0 | FR5: =IF(AZ5="",0,($C5/2+IF(47=$D5,100,0))*EXP(-DI5*((AZ5-Settle)/365))) -> 0 | FS5: =IF(BA5="",0,($C5/2+IF(48=$D5,100,0))*EXP(-DJ5*((BA5-Settle)/365))) -> 0 | FT5: =IF(BB5="",0,($C5/2+IF(49=$D5,100,0))*EXP(-DK5*((BB5-Settle)/365))) -> 0 | FU5: =IF(BC5="",0,($C5/2+IF(50=$D5,100,0))*EXP(-DL5*((BC5-Settle)/365))) -> 0 | FV5: =IF(BD5="",0,($C5/2+IF(51=$D5,100,0))*EXP(-DM5*((BD5-Settle)/365))) -> 0 | FW5: =IF(BE5="",0,($C5/2+IF(52=$D5,100,0))*EXP(-DN5*((BE5-Settle)/365))) -> 0 | FX5: =IF(BF5="",0,($C5/2+IF(53=$D5,100,0))*EXP(-DO5*((BF5-Settle)/365))) -> 0 | FY5: =IF(BG5="",0,($C5/2+IF(54=$D5,100,0))*EXP(-DP5*((BG5-Settle)/365))) -> 0 | FZ5: =IF(BH5="",0,($C5/2+IF(55=$D5,100,0))*EXP(-DQ5*((BH5-Settle)/365))) -> 0 | GA5: =IF(BI5="",0,($C5/2+IF(56=$D5,100,0))*EXP(-DR5*((BI5-Settle)/365))) -> 0 | GB5: =IF(BJ5="",0,($C5/2+IF(57=$D5,100,0))*EXP(-DS5*((BJ5-Settle)/365))) -> 0 | GC5: =IF(BK5="",0,($C5/2+IF(58=$D5,100,0))*EXP(-DT5*((BK5-Settle)/365))) -> 0 | GD5: =IF(BL5="",0,($C5/2+IF(59=$D5,100,0))*EXP(-DU5*((BL5-Settle)/365))) -> 0 | GE5: =IF(BM5="",0,($C5/2+IF(60=$D5,100,0))*EXP(-DV5*((BM5-Settle)/365))) -> 0
